Workbook
Name Slicer_Category: #N/A
Name Slicer_department_name: #N/A
Name Slicer_region: #N/A
Name Timeline_hire_date: #N/A
Name Timeline_release_date: #N/A

Sheet Products
A1: product_id | B1: product_name | C1: category | D1: release_date | E1: price
A2: 8 | B2: H100 Tensor Core | C2: AI Accelerator | D2: 44844 | E2: 19999.99
A3: 7 | B3: A100 Tensor Core | C3: AI Accelerator | D3: 44392 | E3: 14999.99
A4: 6 | B4: DGX Station | C4: Server | D4: 45139 | E4: 8999.99
A5: 15 | B5: NVIDIA Quadro GV100 | C5: GPU | D5: 43205 | E5: 8999
A6: 13 | B6: NVIDIA V100 | C6: AI Accelerator | D6: 42896 | E6: 8000
A7: 10 | B7: Titan V | C7: GPU | D7: 43076 | E7: 2999.99
A8: 14 | B8: NVIDIA A40 | C8: AI Accelerator | D8: 44089 | E8: 2500
A9: 5 | B9: Jetson AGX Orin | C9: AI Accelerator | D9: 45087 | E9: 1999.99
A10: 1 | B10: RTX 4090 | C10: GPU | D10: 44941 | E10: 1599.99
A11: 2 | B11: RTX 4080 | C11: GPU | D11: 44881 | E11: 1199.99
A12: 3 | B12: RTX 4070 | C12: GPU | D12: 44993 | E12: 599.99
A13: 12 | B13: GeForce GTX 1080 | C13: GPU | D13: 42517 | E13: 499.99
... A16: 4 | B16: Jetson Nano | C16: AI Accelerator | D16: 44701 | E16: 99.99

Sheet Customers
A1: customer_id | B1: customer_name | C1: industry | D1: contact_email | E1: contact_phone
A2: 1 | B2: Vega Ltd | C2: AI | D2: vega_ltd@business.com | E2: 710-863-1100x3762
A3: 2 | B3: Smith, Clayton and Ortiz | C3: Research | D3: smith_clayton_and_ortiz@business.com | E3: 734-646-5920
A4: 3 | B4: Mcguire PLC | C4: Gaming | D4: mcguire_plc@business.com | E4: +1-576-934-0732x98777
A5: 4 | B5: Yang-Thompson | C5: Cloud Services | D5: yang-thompson@business.com | E5: +1-845-451-1026x8681
A6: 5 | B6: Savage, Obrien and Zuniga | C6: Data Centers | D6: savage_obrien_and_zuniga@business.com | E6: (760)882-7324x54956
A7: 6 | B7: Villegas and Sons | C7: Data Centers | D7: villegas_and_sons@business.com | E7: 2899975469
A8: 7 | B8: Li, Rodgers and Contreras | C8: Gaming | D8: li_rodgers_and_contreras@business.com | E8: 232.392.3098x930
A9: 8 | B9: Brown, Vaughn and Rivera | C9: Gaming | D9: brown_vaughn_and_rivera@business.com | E9: 213-716-9801
A10: 9 | B10: Davis, Greene and Garcia | C10: Cloud Services | D10: davis_greene_and_garcia@business.com | E10: 577-519-5390
A11: 10 | B11: Rios, Gordon and Roberts | C11: Research | D11: rios_gordon_and_roberts@business.com | E11: (568)541-6684x9320
A12: 11 | B12: Davidson-Perez | C12: Research | D12: davidson-perez@business.com | E12: +1-675-230-2465x366
A13: 12 | B13: Edwards-Anderson | C13: Gaming | D13: edwards-anderson@business.com | E13: +1-278-466-5993x9170
A14: 13 | B14: Wood, Brown and Taylor | C14: AI | D14: wood_brown_and_taylor@business.com | E14: 839-634-8814
A15: 14 | B15: Gonzalez-Harris | C15: Data Centers | D15: gonzalez-harris@business.com | E15: 9813390546
A16: 15 | B16: Mcfarland Ltd | C16: Data Centers | D16: mcfarland_ltd@business.com | E16: 474.968.1771x1997
A17: 16 | B17: Jones, Lambert and Heath | C17: Data Centers | D17: jones_lambert_and_heath@business.com | E17: 351.771.6113x8558
A18: 17 | B18: Friedman Inc | C18: Gaming | D18: friedman_inc@business.com | E18: (746)828-7097x696
A19: 18 | B19: Pope-Adkins | C19: Cloud Services | D19: pope-adkins@business.com | E19: 653.709.0217
A20: 19 | B20: Smith Inc | C20: Cloud Services | D20: smith_inc@business.com | E20: 6085629016
A21: 20 | B21: Melendez, Knapp and Gregory | C21: Data Centers | D21: melendez_knapp_and_gregory@business.com | E21: (566)910-1168x9925

Sheet Sales
A1: sale_id | B1: product_id | C1: customer_id | D1: Category | E1: sale_date | F1: region | G1: quantity_sold | H1: revenue
A2: 1 | B2: 12 | C2: 18 | D2: =_xlfn.XLOOKUP(Sales[[#This Row],[product_id]],Products!A:A,Products!C:C) -> GPU | E2: 45686 | F2: Africa | G2: 409 | H2: 90550.1
A3: 2 | B3: 2 | C3: 10 | D3: =_xlfn.XLOOKUP(Sales[[#This Row],[product_id]],Products!A:A,Products!C:C) -> GPU | E3: 45677 | F3: North America | G3: 374 | H3: 79099.84
A4: 3 | B4: 15 | C4: 2 | D4: =_xlfn.XLOOKUP(Sales[[#This Row],[product_id]],Products!A:A,Products!C:C) -> GPU | E4: 45668 | F4: Asia | G4: 114 | H4: 145538.39
A5: 4 | B5: 3 | C5: 9 | D5: =_xlfn.XLOOKUP(Sales[[#This Row],[product_id]],Products!A:A,Products!C:C) -> GPU | E5: 45685 | F5: Africa | G5: 115 | H5: 19862.17
A6: 5 | B6: 11 | C6: 14 | D6: =_xlfn.XLOOKUP(Sales[[#This Row],[product_id]],Products!A:A,Products!C:C) -> GPU | E6: 45666 | F6: North America | G6: 296 | H6: 120375.83
A7: 6 | B7: 14 | C7: 4 | D7: =_xlfn.XLOOKUP(Sales[[#This Row],[product_id]],Products!A:A,Products!C:C) -> AI Accelerator | E7: 45663 | F7: Asia | G7: 475 | H7: 55142.55
A8: 7 | B8: 2 | C8: 20 | D8: =_xlfn.XLOOKUP(Sales[[#This Row],[product_id]],Products!A:A,Products!C:C) -> GPU | E8: 45666 | F8: Asia | G8: 356 | H8: 84978.9
A9: 8 | B9: 12 | C9: 1 | D9: =_xlfn.XLOOKUP(Sales[[#This Row],[product_id]],Products!A:A,Products!C:C) -> GPU | E9: 45667 | F9: Europe | G9: 242 | H9: 76699.42
A10: 9 | B10: 2 | C10: 6 | D10: =_xlfn.XLOOKUP(Sales[[#This Row],[product_id]],Products!A:A,Products!C:C) -> GPU | E10: 45673 | F10: Europe | G10: 455 | H10: 40178.64
A11: 10 | B11: 8 | C11: 9 | D11: =_xlfn.XLOOKUP(Sales[[#This Row],[product_id]],Products!A:A,Products!C:C) -> AI Accelerator | E11: 45665 | F11: Africa | G11: 447 | H11: 133521.18
A12: 11 | B12: 15 | C12: 13 | D12: =_xlfn.XLOOKUP(Sales[[#This Row],[product_id]],Products!A:A,Products!C:C) -> GPU | E12: 45679 | F12: Africa | G12: 259 | H12: 88538.2
A13: 12 | B13: 4 | C13: 2 | D13: =_xlfn.XLOOKUP(Sales[[#This Row],[product_id]],Products!A:A,Products!C:C) -> AI Accelerator | E13: 45686 | F13: Asia | G13: 333 | H13: 121191.69
... A101: 100 | B101: 14 | C101: 2 | D101: =_xlfn.XLOOKUP(Sales[[#This Row],[product_id]],Products!A:A,Products!C:C) -> AI Accelerator | E101: 45666 | F101: North America | G101: 446 | H101: 90546.9

Sheet Category
A1: Category
A2: GPU
A3: AI Accelerator
A4: Server

Sheet Suppliers
A1: supplier_id | B1: supplier_name | C1: material_supplied | D1: contact_email
A2: 1 | B2: Cochran-Williams | C2: AI Chips | D2: cochran-williams@supplier.com
A3: 2 | B3: Reed, Schmidt and Pineda | C3: Microcontrollers | D3: reed_schmidt_and_pineda@supplier.com
A4: 3 | B4: Madden Group | C4: Batteries | D4: madden_group@supplier.com
A5: 4 | B5: Lyons, Smith and Jimenez | C5: Memory Chips | D5: lyons_smith_and_jimenez@supplier.com
A6: 5 | B6: Miller PLC | C6: Memory Chips | D6: miller_plc@supplier.com
A7: 6 | B7: Snyder, Williams and Clark | C7: Capacitors | D7: snyder_williams_and_clark@supplier.com
A8: 7 | B8: Martin, Mccormick and Pope | C8: Resistors | D8: martin_mccormick_and_pope@supplier.com
A9: 8 | B9: Phillips, Taylor and Sanchez | C9: Batteries | D9: phillips_taylor_and_sanchez@supplier.com
A10: 9 | B10: James and Sons | C10: PCB | D10: james_and_sons@supplier.com
A11: 10 | B11: Holt, Burton and Powell | C11: Batteries | D11: holt_burton_and_powell@supplier.com
A12: 11 | B12: Gardner, Werner and Davis | C12: Batteries | D12: gardner_werner_and_davis@supplier.com
A13: 12 | B13: Jones and Sons | C13: Silicon | D13: jones_and_sons@supplier.com
... A51: 50 | B51: Scott-Aguilar | C51: Memory Chips | D51: scott-aguilar@supplier.com

Sheet Supply Chain 
A1: supply_chain_id | B1: supplier_id | C1: product_id | D1: supply_date | E1: quantity_supplied | F1: Category
A2: 1 | B2: 39 | C2: 1 | D2: 45667 | E2: 2830 | F2: =_xlfn.XLOOKUP(Supply_Chain[[#This Row],[product_id]],Products!A:A,Products!C:C) -> GPU
A3: 2 | B3: 43 | C3: 9 | D3: 45671 | E3: 4081 | F3: =_xlfn.XLOOKUP(Supply_Chain[[#This Row],[product_id]],Products!A:A,Products!C:C) -> GPU
A4: 3 | B4: 12 | C4: 3 | D4: 45675 | E4: 3865 | F4: =_xlfn.XLOOKUP(Supply_Chain[[#This Row],[product_id]],Products!A:A,Products!C:C) -> GPU
A5: 4 | B5: 38 | C5: 4 | D5: 45678 | E5: 1454 | F5: =_xlfn.XLOOKUP(Supply_Chain[[#This Row],[product_id]],Products!A:A,Products!C:C) -> AI Accelerator
A6: 5 | B6: 44 | C6: 9 | D6: 45683 | E6: 3766 | F6: =_xlfn.XLOOKUP(Supply_Chain[[#This Row],[product_id]],Products!A:A,Products!C:C) -> GPU
A7: 6 | B7: 2 | C7: 11 | D7: 45681 | E7: 2715 | F7: =_xlfn.XLOOKUP(Supply_Chain[[#This Row],[product_id]],Products!A:A,Products!C:C) -> GPU
A8: 7 | B8: 11 | C8: 5 | D8: 45670 | E8: 4984 | F8: =_xlfn.XLOOKUP(Supply_Chain[[#This Row],[product_id]],Products!A:A,Products!C:C) -> AI Accelerator
A9: 8 | B9: 37 | C9: 13 | D9: 45676 | E9: 2324 | F9: =_xlfn.XLOOKUP(Supply_Chain[[#This Row],[product_id]],Products!A:A,Products!C:C) -> AI Accelerator
A10: 9 | B10: 16 | C10: 15 | D10: 45684 | E10: 3562 | F10: =_xlfn.XLOOKUP(Supply_Chain[[#This Row],[product_id]],Products!A:A,Products!C:C) -> GPU
A11: 10 | B11: 36 | C11: 3 | D11: 45676 | E11: 4119 | F11: =_xlfn.XLOOKUP(Supply_Chain[[#This Row],[product_id]],Products!A:A,Products!C:C) -> GPU
A12: 11 | B12: 15 | C12: 13 | D12: 45669 | E12: 3214 | F12: =_xlfn.XLOOKUP(Supply_Chain[[#This Row],[product_id]],Products!A:A,Products!C:C) -> AI Accelerator
A13: 12 | B13: 39 | C13: 9 | D13: 45682 | E13: 1184 | F13: =_xlfn.XLOOKUP(Supply_Chain[[#This Row],[product_id]],Products!A:A,Products!C:C) -> GPU
... A101: 100 | B101: 47 | C101: 15 | D101: 45676 | E101: 4555 | F101: =_xlfn.XLOOKUP(Supply_Chain[[#This Row],[product_id]],Products!A:A,Products!C:C) -> GPU

Sheet Department
A1: department_id | B1: department_name | C1: States | D1: location
A2: 1 | B2: R&D | C2: Arizona | D2: Santa Clara
A3: 2 | B3: Sales | C3: New York | D3: New York
A4: 3 | B4: Operations | C4: Texas | D4: Austin
A5: 4 | B5: Marketing | C5: California | D5: Los Angeles
A6: 5 | B6: HR | C6: Washington | D6: Seattle

Sheet Employees
A1: employee_id | B1: first_name | C1: last_name | D1: department_id | E1: hire_date | F1: Month | G1: salary
A2: 1 | B2: Matthew | C2: Crosby | D2: 2 | E2: 44576 | F2: =TEXT(Employees[[#This Row],[hire_date]],"mmmm") -> January | G2: 84701.82
A3: 2 | B3: Tina | C3: Carter | D3: 3 | E3: 44586 | F3: =TEXT(Employees[[#This Row],[hire_date]],"mmmm") -> January | G3: 144435.89
A4: 3 | B4: Amber | C4: Johnson | D4: 2 | E4: 44396 | F4: =TEXT(Employees[[#This Row],[hire_date]],"mmmm") -> July | G4: 68735.54
A5: 4 | B5: Debra | C5: Pope | D5: 5 | E5: 44477 | F5: =TEXT(Employees[[#This Row],[hire_date]],"mmmm") -> October | G5: 125624.7
A6: 5 | B6: Craig | C6: Joseph | D6: 4 | E6: 45516 | F6: =TEXT(Employees[[#This Row],[hire_date]],"mmmm") -> August | G6: 139787.82
A7: 6 | B7: Benjamin | C7: Jones | D7: 1 | E7: 45068 | F7: =TEXT(Employees[[#This Row],[hire_date]],"mmmm") -> May | G7: 123300.29
A8: 7 | B8: Rachel | C8: Ingram | D8: 4 | E8: 44504 | F8: =TEXT(Employees[[#This Row],[hire_date]],"mmmm") -> November | G8: 109605.69
A9: 8 | B9: Tara | C9: Contreras | D9: 2 | E9: 44464 | F9: =TEXT(Employees[[#This Row],[hire_date]],"mmmm") -> September | G9: 96563.44
A10: 9 | B10: Juan | C10: Carroll | D10: 4 | E10: 44281 | F10: =TEXT(Employees[[#This Row],[hire_date]],"mmmm") -> March | G10: 87326.23
A11: 10 | B11: Zachary | C11: Ruiz | D11: 2 | E11: 45191 | F11: =TEXT(Employees[[#This Row],[hire_date]],"mmmm") -> September | G11: 122117.74
A12: 11 | B12: William | C12: Williams | D12: 3 | E12: 44034 | F12: =TEXT(Employees[[#This Row],[hire_date]],"mmmm") -> July | G12: 147124.08
A13: 12 | B13: Maria | C13: Salas | D13: 5 | E13: 45516 | F13: =TEXT(Employees[[#This Row],[hire_date]],"mmmm") -> August | G13: 83832.84
... A31: 30 | B31: Tyler | C31: Wilson | D31: 1 | E31: 43878 | F31: =TEXT(Employees[[#This Row],[hire_date]],"mmmm") -> February | G31: 149677.62

Sheet Projects
A1: project_id | B1: project_name | C1: department_id | D1: start_date | E1: end_date | F1: Project Duration | G1: budget
A2: 1 | B2: leverage synergistic markets | C2: 3 | D2: 43861 | E2: 44808 | F2: =E2-D2 -> 947 | G2: 718591.55
A3: 2 | B3: empower best-of-breed metrics | C3: 4 | D3: 44959 | E3: 45514 | F3: =E3-D3 -> 555 | G3: 678105.92
A4: 3 | B4: grow sticky eyeballs | C4: 3 | D4: 44939 | E4: 45218 | F4: =E4-D4 -> 279 | G4: 652174
A5: 4 | B5: reinvent frictionless e-tailers | C5: 4 | D5: 44745 | E5: 45418 | F5: =E5-D5 -> 673 | G5: 275175.63
A6: 5 | B6: drive turn-key methodologies | C6: 4 | D6: 44418 | E6: 45369 | F6: =E6-D6 -> 951 | G6: 660738.81
A7: 6 | B7: incubate back-end e-services | C7: 2 | D7: 44548 | E7: 45388 | F7: =E7-D7 -> 840 | G7: 154606.53
A8: 7 | B8: e-enable bricks-and-clicks functionalities | C8: 2 | D8: 45363 | E8: 45649 | F8: =E8-D8 -> 286 | G8: 858382.25
A9: 8 | B9: facilitate customized relationships | C9: 2 | D9: 45136 | E9: 45446 | F9: =E9-D9 -> 310 | G9: 735757
A10: 9 | B10: re-contextualize user-centric users | C10: 5 | D10: 44576 | E10: 45012 | F10: =E10-D10 -> 436 | G10: 863969.44
A11: 10 | B11: exploit integrated interfaces | C11: 5 | D11: 44258 | E11: 45111 | F11: =E11-D11 -> 853 | G11: 757313.53

Sheet Meta Data
A1: Sheet Name | B1: Field Name | C1: Data Type | D1: Range of Values | E1: Meaning of the Field | F1: Data Source and History | G1: Data Quality | H1: Data Structure
A2: Products | B2: product_id | C2: Number | D2: 1 to 15 | E2: Unique number to identify each product in the list | F2: Compay database
A3: Products | B3: product_name | C3: Text | D3: No specific range | E3: The name of the product | F3: Compay database
A4: Products | B4: category | C4: Text | D4: GPU, AI Accelerator, Server | E4: The category of the product | F4: Compay database
A5: Products | B5: release_date | C5: Date | D5: 2016 to 2023 | E5: The date when the product was released | F5: Compay database
A6: Products | B6: price | C6: Number | D6: 99.99 to 19,999 | E6: The price of the product | F6: Compay database
A7: Customers | B7: customer_id | C7: Number | D7: 1 to 20 | E7: Unique identifier for each customer in the list | F7: Compay database
A8: Customers | B8: customer_name | C8: Text | D8: No specific range | E8: The name of the custmer | F8: Compay database
A9: Customers | B9: industry | C9: Text | D9: industry, AI, Research, Gaming, Cloud Services, Data Centers | E9: The industy of the customer | F9: Compay database
A10: Customers | B10: contact_email | C10: Text | D10: No specific range | E10: The email of the customer | F10: Compay database
A11: Customers | B11: contact_phone | C11: Text | D11: No specific range | E11: The contact phone number of the customer | F11: Compay database
A12: Sales | B12: sale_id | C12: Number | D12: 1 to 100 | E12: Unique identifier for each sale in the list | F12: Compay database
A13: Sales | B13: product_id | C13: Number | D13: 1 to 15 | E13: Unique identifier for each product in the list | F13: Compay database
A14: Sales | B14: customer_id | C14: Number | D14: 1 to 20 | E14: Unique identifier for each customer in the list | F14: Compay database
A15: Sales | B15: sale_date | C15: Number | D15: 45658 to 45686 | E15: The date when the sale was made | F15: Compay database | G15: Wrong Data Type
A16: Sales | B16: region | C16: Text | D16: Africa, North America, Asia, Europe | E16: The name of the geographical area by continent | F16: Compay database
A17: Sales | B17: quantity_sold | C17: Number | D17: 11 to 491 | E17: The number of units of the products sold (per sale ID) | F17: Compay database
A18: Sales | B18: revenue | C18: Number | D18: No specific range | E18: The total revenue of the products sold (per sale ID) | F18: Compay database
A19: Suppliers | B19: supplier_id | C19: Number | D19: 1 to 50 | E19: Unique number to identify each customer in the list | F19: Compay database
A20: Suppliers | B20: supplier_name | C20: Text | D20: No specific range | E20: The name of the supplier | F20: Compay database
A21: Suppliers | B21: material_supplied | C21: Text | D21: AI Chips, Microcontrollers, Batteries, Memory Chips, Capacitors, Resistors, PCB, Silicon | E21: The name of the material supplied | F21: Compay database
A22: Suppliers | B22: contact_email | C22: Text | D22: No specific range | E22: The contact phone number of the supplier | F22: Compay database
A23: Supply Chain | B23: supply_chain_id | C23: Number | D23: 1 to 100 | E23: Unique number to identify each supply chain in the list | F23: Compay database
A24: Supply Chain | B24: supplier_id | C24: Number | D24: No specific range | E24: Unique identifier for each supplier in the list | F24: Compay database
A25: Supply Chain | B25: product_id | C25: Number | D25: 1 to 15 | E25: Unique identifier for each product in the list | F25: Compay database
A26: Supply Chain | B26: supply_date | C26: Number | D26: 45658 to 45686 | E26: The date when the product were provided | F26: Compay database | G26: Wrong Data Type
A27: Supply Chain | B27: quantity_supplied | C27: Number | D27: No specific range | E27: The number of units of the products supplied (per supply chain ID) | F27: Compay database
A28: Department | B28: department_id | C28: Date | D28: 1 to 5 | E28: Unique identifier for each department | F28: Compay database | G28: Wrong Data Type
A29: Department | B29: department_name | C29: Text | D29: No specific range | E29: The name of the department | F29: Compay database
A30: Department | B30: location | C30: Text | D30: No specific range | E30: The name of the geographical area by city | F30: Compay database
A31: Employees | B31: employee_id | C31: Date | D31: 1 to 31 | E31: Unique identifier for each employee | F31: Compay database | G31: Wrong Data Type
A32: Employees | B32: first_name | C32: Text | D32: No specific range | E32: The first name of the employees | F32: Compay database
A33: Employees | B33: last_name | C33: Text | D33: No specific range | E33: The last name of the employees | F33: Compay database
A34: Employees | B34: department_id | C34: Date | D34: 1 to 5 | E34: Unique identifier for each department | F34: Compay database | G34: Wrong Data Type
A35: Employees | B35: hire_date | C35: Date | D35: 2020 to 2024 | E35: The hiring date of each emplloyee in the list | F35: Compay database
A36: Employees | B36: salary | C36: Date | D36: No specific range | E36: The salary of each employee in the list | F36: Compay database | G36: Wrong Data Type
A37: Projects | B37: project_id | C37: Date | D37: 1 to 10 | E37: Unique identifier for each project | F37: Compay database | G37: Wrong Data Type
A38: Projects | B38: project_name | C38: Text | D38: No specific range | E38: The name of the projects in the list | F38: Compay database
A39: Projects | B39: department_id | C39: Date | D39: 1 to 5 | E39: Unique identifier for each department | F39: Compay database | G39: Wrong Data Type
A40: Projects | B40: start_date | C40: Date | D40: 2020 to 2024 | E40: The starting date of each project in the list | F40: Compay database
...

Sheet SMART Question - Sales
A1: Row Labels | B1: Sum of revenue | C1: Sum of quantity_sold | H1: What is the top 5 products with the highest revenue
A2: GeForce GTX 1080 | B2: 1127507.3 | C2: 3316 | H2: What is the top 5 products sales per quantity
A3: Jetson Nano | B3: 958803.31 | C3: 2092
A4: NVIDIA A40 | B4: 863029.77 | C4: 3012
A5: RTX 4080 | B5: 840037.87 | C5: 2337
A6: RTX 4070 | B6: 809514.24 | C6: 2728
A7: Grand Total | B7: 4598892.5 | C7: 13485
A18: Row Labels | B18: Sum of revenue | H18: What is the contribution of each region in the revenue
A19: Africa | B19: 2104851.2
A20: Asia | B20: 1902979.1
A21: Europe | B21: 3328763.8
A22: North America | B22: 3064073.5
A23: Grand Total | B23: 10400668
A33: Row Labels | B33: Sum of revenue | H33: What is the revenue contribution for each category
A34: AI Accelerator | B34: 4639658.7
A35: GPU | B35: 5047801.5
A36: Server | B36: 713207.42
A37: Grand Total | B37: 10400668
A50: Row Labels | B50: Sum of revenue | H50: What is the revenue contribution for each industy
A51: AI | B51: 1041160.2
A52: Cloud Services | B52: 1894515.9
A53: Data Centers | B53: 3031637.2
A54: Gaming | B54: 2536222.3
A55: Research | B55: 1897132.1
A56: Grand Total | B56: 10400668
A66: Row Labels | B66: Sum of quantity_supplied | H66: What is the highest quantity supplier for top 5 products
A67: Bishop, Davis and Brooks | B67: 25758
A68: Gonzalez-Buck | B68: 17623
A69: Hill Ltd | B69: 14714
A70: Shaffer, Baird and Barajas | B70: 14391
A71: Grimes, Wilkerson and Martinez | B71: 13317
A72: Jones and Sons | B72: 12571
A73: Espinoza LLC | B73: 11804
A74: Miller PLC | B74: 11200
A75: Wright-Williams | B75: 10728
A76: Foster-Smith | B76: 10467
A77: Grand Total | B77: 142573
H83: What are the most frequent material supplied for each category
A84: Sum of quantity_supplied | B84: Column Labels
A85: Row Labels | B85: AI Accelerator | C85: GPU | D85: Server | E85: Grand Total
...

Sheet SMART Question - Project
A3: Row Labels | B3: Sum of budget | C3: Sum of Project Duration
A4: drive turn-key methodologies | B4: 660738.81 | C4: 951
A5: e-enable bricks-and-clicks functionalities | B5: 858382.25 | C5: 286
A6: empower best-of-breed metrics | B6: 678105.92 | C6: 555
A7: exploit integrated interfaces | B7: 757313.53 | C7: 853
A8: facilitate customized relationships | B8: 735757 | C8: 310
A9: grow sticky eyeballs | B9: 652174 | C9: 279
A10: incubate back-end e-services | B10: 154606.53 | C10: 840
A11: leverage synergistic markets | B11: 718591.55 | C11: 947
A12: re-contextualize user-centric users | B12: 863969.44 | C12: 436
A13: reinvent frictionless e-tailers | B13: 275175.63 | C13: 673
A14: Grand Total | B14: 6354814.7 | C14: 6130
A21: Row Labels | B21: Sum of budget
A22: re-contextualize user-centric users | B22: 863969.44
A23: e-enable bricks-and-clicks functionalities | B23: 858382.25
A24: exploit integrated interfaces | B24: 757313.53
A25: facilitate customized relationships | B25: 735757
A26: leverage synergistic markets | B26: 718591.55
A27: empower best-of-breed metrics | B27: 678105.92
A28: drive turn-key methodologies | B28: 660738.81
A29: grow sticky eyeballs | B29: 652174
A30: reinvent frictionless e-tailers | B30: 275175.63
A31: incubate back-end e-services | B31: 154606.53
A32: Grand Total | B32: 6354814.7
A39: Row Labels | B39: Sum of budget
A40: Operations | B40: 1370765.6
A41: Marketing | B41: 1614020.4
A42: Sales | B42: 1748745.8
A43: HR | B43: 1621283
A44: Grand Total | B44: 6354814.7
A52: Row Labels | B52: Count of employee_id | M52: What's the hiring total for each quarter in the past 5 years
A53: Qtr1 | B53: 9
A54: Qtr2 | B54: 5
A55: Qtr3 | B55: 7
A56: Qtr4 | B56: 9
A57: Grand Total | B57: 30
A69: Row Labels | B69: Average of salary
A70: Sales | B70: 97179.095
A71: HR | B71: 99168.2
A72: Marketing | B72: 107733.33
...

Sheet Dashboard-Sales
A118: Sum of quantity_sold
A119: 13433
A120: Sum of revenue
A121: 10400668

Sheet Dashboard-Project
A200: Count of first_name
A201: 30
A202: Sum of budget
A203: 6354814.7
A204: Count of project_name
A205: 10

Sheet Sheet1
